<?xml version="1.0"?>
<!--
  Gazebo ROS ackermann drive plugin demo

  Try sending commands:

    ros2 topic pub /demo/cmd_demo geometry_msgs/msg/Twist '{linear: {x: 1.0}, angular: {z: 0.1}}' -1

  Try listening to odometry:

    ros2 topic echo /demo/odom_demo

  Try listening to odometer reading(linear distance convered):

    ros2 topic echo /demo/distance_demo

  Try listening to TF:

    ros2 run tf2_ros tf2_echo odom_demo chassis

    and other links
-->
<sdf version="1.6">
  <world name="default">

    <!-- ===== Scene: blue sky with moving clouds + soft ambient ===== -->
    <scene>
      <ambient>0.45 0.45 0.50 1</ambient>
      <background>0.55 0.78 0.98 1</background>
      <shadows>true</shadows>
      <sky>
        <clouds>
          <speed>4</speed>
          <direction>1.2</direction>
          <humidity>0.45</humidity>
          <mean_size>0.55</mean_size>
          <ambient>0.85 0.85 0.85 1</ambient>
        </clouds>
      </sky>
    </scene>

    <!-- ===== Warm afternoon sunlight, casting shadows ===== -->
    <light name="sun" type="directional">
      <cast_shadows>true</cast_shadows>
      <pose>0 0 50 0 0 0</pose>
      <diffuse>1.00 0.93 0.80 1</diffuse>
      <specular>0.45 0.45 0.40 1</specular>
      <attenuation>
        <range>1000</range>
        <constant>0.9</constant>
        <linear>0.01</linear>
        <quadratic>0.001</quadratic>
      </attenuation>
      <direction>-0.45 0.25 -0.85</direction>
    </light>

    <!-- Default ground_plane (light gray). Tinted warm by the sunset light.
         A custom colored plane at z=0 caused Z-fighting with the <road>
         element, making the road flicker / disappear, so we keep the
         stock plane which is proven to render the road correctly. -->
    <include>
      <uri>model://ground_plane</uri>
    </include>


    <model name="autocar">
      <!-- Spawn on the track just before waypoint 0 at (103.67, 0).
           The car's local forward axis is +Y (front wheels are at chassis
           y=+1.517), so yaw=0 makes the car face world +Y, which is the
           counter-clockwise tangent at (103.67, 0). -->
      <pose>103.67 -20.0 0.0 0 0 0</pose>

      <link name='base_link' />

      <joint name='chassis_link_joint' type='fixed'>
        <pose>0.0 0.0 0.0 0 0 0</pose>
        <parent>base_link</parent>
        <child>chassis_link</child>
      </joint>

      <joint name="hokuyo_joint" type="fixed">
        <parent>base_link</parent>
        <child>hokuyo_link</child>
        <pose>0 0 0 0 0 0</pose>
        <axis>
          <xyz>0 0 1</xyz>
        </axis>
      </joint>

      <link name="hokuyo_link">
        <sensor name="head_hokuyo_sensor" type="ray">
          <always_on>true</always_on>
          <visualize>true</visualize>
          <pose relative_to='base_link'>0 2.34 0.72 0 0 1.5708</pose>
          <update_rate>40</update_rate>
          <ray>
            <scan>
              <horizontal>
                <samples>720</samples>
                <resolution>1.000000</resolution>
                <min_angle>-1.570796</min_angle>
                <max_angle>1.570796</max_angle>
              </horizontal>
            </scan>
            <range>
              <min>0.120000</min>
              <max>30.0</max>
              <resolution>0.010</resolution>
            </range>
            <noise>
              <type>gaussian</type>
              <mean>0.0</mean>
              <stddev>0.01</stddev>
            </noise>
          </ray>
          <plugin name="gazebo_ros_head_hokuyo_controller" filename="libgazebo_ros_ray_sensor.so">
            <ros>
              <remapping>~/out:=scan</remapping>
            </ros>
            <output_type>sensor_msgs/LaserScan</output_type>
            <frame_name>hokuyo_link</frame_name>
          </plugin>
        </sensor>
      </link>

      <joint name="third_person_camera_joint" type="fixed">
        <parent>base_link</parent>
        <child>third_person_camera_link</child>
      </joint>

      <link name="third_person_camera_link">
        <pose relative_to="base_link">0 -8 3.5 0 0.25 1.5708</pose>
        <sensor name="third_person_camera" type="camera">
          <always_on>true</always_on>
          <visualize>true</visualize>
          <update_rate>30</update_rate>
          <camera>
            <horizontal_fov>1.2</horizontal_fov>
            <image>
              <width>1280</width>
              <height>720</height>
              <format>R8G8B8</format>
            </image>
            <clip>
              <near>0.1</near>
              <far>300</far>
            </clip>
          </camera>
          <plugin name="third_person_camera_controller" filename="libgazebo_ros_camera.so">
            <ros>
              <namespace>autocar</namespace>
              <remapping>image_raw:=third_person_camera/image_raw</remapping>
              <remapping>camera_info:=third_person_camera/camera_info</remapping>
            </ros>
            <frame_name>third_person_camera_link</frame_name>
          </plugin>
        </sensor>
      </link>

      <link name='chassis_link'>
        <inertial>
          <pose>1e-06 0.07307 0.65096 0 -0 0</pose>
          <mass>1580</mass>
          <inertia>
            <ixx>1997.86</ixx>
            <ixy>-3e-05</ixy>
            <ixz>-1e-06</ixz>
            <iyy>442.769</iyy>
            <iyz>62.5206</iyz>
            <izz>2238.05</izz>
          </inertia>
        </inertial>
        <collision name='chassis_link_fixed_joint_lump__chassis_link_collision'>
          <pose>0 0 0.46936 0 -0 0</pose>
          <geometry>
            <mesh>
              <scale>0.001 0.001 0.001</scale>
              <uri>model://autocar/meshes/chassis_link.stl</uri>
            </mesh>
          </geometry>
          <surface>
            <contact>
              <ode />
            </contact>
            <friction>
              <ode>
                <mu>0.2</mu>
                <mu2>0.2</mu2>
              </ode>
            </friction>
          </surface>
        </collision>
        <collision name='chassis_link_fixed_joint_lump__spoiler_link_collision_1'>
          <pose>0 0.05 0.41936 1.5708 -0 3.14159</pose>
          <geometry>
            <mesh>
              <scale>0.001 0.001 0.001</scale>
              <uri>model://autocar/meshes/spoiler.stl</uri>
            </mesh>
          </geometry>
          <surface>
            <contact>
              <ode />
            </contact>
            <friction>
              <ode>
                <mu>0.2</mu>
                <mu2>0.2</mu2>
              </ode>
            </friction>
          </surface>
        </collision>
        <visual name='chassis_link_fixed_joint_lump__chassis_link_visual'>
          <pose>0 0 0.46936 0 -0 0</pose>
          <geometry>
            <mesh>
              <scale>0.001 0.001 0.001</scale>
              <uri>model://autocar/meshes/chassis_link.stl</uri>
            </mesh>
          </geometry>
          <!-- Glossy racing red. -->
          <material>
            <ambient>0.35 0.02 0.02 1</ambient>
            <diffuse>0.85 0.05 0.05 1</diffuse>
            <specular>0.9 0.9 0.9 1</specular>
            <emissive>0.04 0.0 0.0 1</emissive>
          </material>
        </visual>
        <visual name='chassis_link_fixed_joint_lump__spoiler_link_visual_1'>
          <pose>0 0.05 0.41936 1.5708 -0 3.14159</pose>
          <geometry>
            <mesh>
              <scale>0.001 0.001 0.001</scale>
              <uri>model://autocar/meshes/spoiler.stl</uri>
            </mesh>
          </geometry>
          <!-- Matte carbon-black spoiler. -->
          <material>
            <ambient>0.02 0.02 0.02 1</ambient>
            <diffuse>0.08 0.08 0.08 1</diffuse>
            <specular>0.2 0.2 0.2 1</specular>
          </material>
        </visual>
        <!-- <velocity_decay/> -->
        <!--  <gravity>1</gravity> -->
        <!--  <gravity>1</gravity> -->
        <!-- <velocity_decay/> -->
        <self_collide>1</self_collide>
        <!--  <gravity>1</gravity> -->
      </link>

      <joint name='bl_axle' type='revolute'>
        <pose relative_to='chassis_link'>-0.875 -1.01364 0.324997 0 -0 0</pose>
        <parent>chassis_link</parent>
        <child>bl_1</child>
        <axis>
          <xyz>-1 0 0</xyz>
          <dynamics>
            <friction>12.031606150200002</friction>
          </dynamics>
        </axis>
      </joint>
      <link name='bl_1'>
        <pose relative_to='bl_axle'>0 0 0 0 -0 0</pose>
        <inertial>
          <pose>-0.0377 0 -0 0 -0 0</pose>
          <mass>24.5</mass>
          <inertia>
            <ixx>1.84514</ixx>
            <ixy>0</ixy>
            <ixz>0</ixz>
            <iyy>1.04961</iyy>
            <iyz>0</iyz>
            <izz>1.04961</izz>
          </inertia>
        </inertial>
        <collision name='bl_1_collision'>
          <pose relative_to='bl_axle'>0 0 0 0 1.5708 0</pose>
          <geometry>
            <cylinder>
              <radius>.3425</radius>
              <length>.22</length>
            </cylinder>
          </geometry>
          <surface>
            <contact>
              <ode />
            </contact>
            <friction>
              <ode>
                <mu>1.7</mu>
                <mu2>1.7</mu2>
              </ode>
            </friction>
          </surface>
        </collision>
        <visual name='bl_1_visual'>
          <pose>0.875 1.0136 0.1444 0 -0 0</pose>
          <geometry>
            <mesh>
              <scale>0.001 0.001 0.001</scale>
              <uri>model://autocar/meshes/bl_1.stl</uri>
            </mesh>
          </geometry>
          <material>
            <ambient>0.02 0.02 0.02 1</ambient>
            <diffuse>0.1 0.1 0.1 1</diffuse>
            <specular>0.4 0.4 0.4 1</specular>
          </material>
        </visual>
        <!--  <gravity>1</gravity> -->
        <!-- <velocity_decay/> -->
        <self_collide>1</self_collide>
      </link>
      <joint name='br_axle' type='revolute'>
        <pose relative_to='chassis_link'>0.875 -1.01364 0.324997 0 -0 0</pose>
        <parent>chassis_link</parent>
        <child>br_1</child>
        <axis>
          <xyz>-1 0 0</xyz>
          <dynamics>
            <friction>12.031606150200002</friction>
          </dynamics>
        </axis>
      </joint>
      <link name='br_1'>
        <pose relative_to='br_axle'>0 0 0 0 -0 0</pose>
        <inertial>
          <pose>-0.0377 0 -0 0 -0 0</pose>
          <mass>24.5</mass>
          <inertia>
            <ixx>1.84514</ixx>
            <ixy>0</ixy>
            <ixz>0</ixz>
            <iyy>1.04961</iyy>
            <iyz>0</iyz>
            <izz>1.04961</izz>
          </inertia>
        </inertial>
        <collision name='br_1_collision'>
          <pose relative_to='br_axle'>0 0 0 0 1.5708 0</pose>
          <geometry>
            <cylinder>
              <radius>.3425</radius>
              <length>.22</length>
            </cylinder>
          </geometry>
          <surface>
            <contact>
              <ode />
            </contact>
            <friction>
              <ode>
                <mu>1.7</mu>
                <mu2>1.7</mu2>
              </ode>
            </friction>
          </surface>
        </collision>
        <visual name='br_1_visual'>
          <pose>-0.875 1.0136 0.1444 0 -0 0</pose>
          <geometry>
            <mesh>
              <scale>0.001 0.001 0.001</scale>
              <uri>model://autocar/meshes/br_1.stl</uri>
            </mesh>
          </geometry>
          <material>
            <ambient>0.02 0.02 0.02 1</ambient>
            <diffuse>0.1 0.1 0.1 1</diffuse>
            <specular>0.4 0.4 0.4 1</specular>
          </material>
        </visual>
        <!--  <gravity>1</gravity> -->
        <!-- <velocity_decay/> -->
        <self_collide>1</self_collide>
      </link>
      <joint name='l_steer' type='revolute'>
        <pose relative_to='chassis_link'>-0.825 1.51736 0.324997 0 -0 0</pose>
        <parent>chassis_link</parent>
        <child>l_steer_1</child>
        <axis>
          <xyz>0 0 1</xyz>
          <limit>
            <lower>-0.95</lower>
            <upper>0.95</upper>
          </limit>
          <dynamics>
            <friction>18.0474092253</friction>
          </dynamics>
        </axis>
      </joint>
      <link name='l_steer_1'>
        <pose relative_to='l_steer'>0 0 0 0 -0 0</pose>
        <inertial>
          <pose>0.003381 0 0.02162 0 -0 0</pose>
          <mass>1</mass>
          <inertia>
            <ixx>1</ixx>
            <ixy>0</ixy>
            <ixz>0</ixz>
            <iyy>1</iyy>
            <iyz>0</iyz>
            <izz>1</izz>
          </inertia>
        </inertial>
        <!--  <gravity>1</gravity> -->
        <!-- <velocity_decay/> -->
        <self_collide>1</self_collide>
      </link>

      <joint name='fl_axle' type='revolute'>
        <pose relative_to='l_steer_1'>-0.05 0 0 0 -0 0</pose>
        <parent>l_steer_1</parent>
        <child>fl_1</child>
        <axis>
          <xyz>-1 0 0</xyz>
          <dynamics>
            <friction>12.031606150200002</friction>
          </dynamics>
        </axis>
      </joint>
      <link name='fl_1'>
        <pose relative_to='fl_axle'>0 0 0 0 -0 0</pose>
        <inertial>
          <pose>-0.0377 0 -0 0 -0 0</pose>
          <mass>24.5</mass>
          <inertia>
            <ixx>1.84514</ixx>
            <ixy>0</ixy>
            <ixz>0</ixz>
            <iyy>1.04961</iyy>
            <iyz>0</iyz>
            <izz>1.04961</izz>
          </inertia>
        </inertial>
        <collision name='fl_1_collision'>
          <pose>0.875 -1.5174 0.1444 0 -0 0</pose>
          <geometry>
            <mesh>
              <scale>0.001 0.001 0.001</scale>
              <uri>model://autocar/meshes/fl_1.stl</uri>
            </mesh>
          </geometry>
          <surface>
            <contact>
              <ode />
            </contact>
            <friction>
              <ode>
                <mu>1.1</mu>
                <mu2>1.1</mu2>
              </ode>
            </friction>
          </surface>
        </collision>
        <visual name='fl_1_visual'>
          <pose>0.875 -1.5174 0.1444 0 -0 0</pose>
          <geometry>
            <mesh>
              <scale>0.001 0.001 0.001</scale>
              <uri>model://autocar/meshes/fl_1.stl</uri>
            </mesh>
          </geometry>
          <material>
            <ambient>0.02 0.02 0.02 1</ambient>
            <diffuse>0.1 0.1 0.1 1</diffuse>
            <specular>0.4 0.4 0.4 1</specular>
          </material>
        </visual>
        <!--  <gravity>1</gravity> -->
        <!-- <velocity_decay/> -->
        <self_collide>1</self_collide>
      </link>
      <joint name='r_steer' type='revolute'>
        <pose relative_to='chassis_link'>0.825 1.51736 0.324997 0 -0 0</pose>
        <parent>chassis_link</parent>
        <child>r_steer_1</child>
        <axis>
          <xyz>0 0 1</xyz>
          <limit>
            <lower>-0.95</lower>
            <upper>0.95</upper>
          </limit>
          <dynamics>
            <damping>0.01</damping>
            <friction>18.0474092253</friction>
          </dynamics>
        </axis>
      </joint>
      <link name='r_steer_1'>
        <pose relative_to='r_steer'>0 0 0 0 -0 0</pose>
        <inertial>
          <pose>0.003381 0 0.02162 0 -0 0</pose>
          <mass>1</mass>
          <inertia>
            <ixx>1</ixx>
            <ixy>0</ixy>
            <ixz>0</ixz>
            <iyy>1</iyy>
            <iyz>0</iyz>
            <izz>1</izz>
          </inertia>
        </inertial>
        <!--  <gravity>1</gravity> -->
        <!-- <velocity_decay/> -->
        <self_collide>1</self_collide>
      </link>
      <joint name='fr_axle' type='revolute'>
        <pose relative_to='r_steer_1'>0.05 0 0 0 -0 0</pose>
        <parent>r_steer_1</parent>
        <child>fr_1</child>
        <axis>
          <xyz>-1 0 0</xyz>
          <dynamics>
            <friction>12.031606150200002</friction>
          </dynamics>
        </axis>
      </joint>
      <link name='fr_1'>
        <pose relative_to='fr_axle'>0 0 0 0 -0 0</pose>
        <inertial>
          <pose>-0.0377 0 -0 0 -0 0</pose>
          <mass>24.5</mass>
          <inertia>
            <ixx>1.84514</ixx>
            <ixy>0</ixy>
            <ixz>0</ixz>
            <iyy>1.04961</iyy>
            <iyz>0</iyz>
            <izz>1.04961</izz>
          </inertia>
        </inertial>
        <collision name='fr_1_collision'>
          <pose>-0.875 -1.5174 0.1444 0 -0 0</pose>
          <geometry>
            <mesh>
              <scale>0.001 0.001 0.001</scale>
              <uri>model://autocar/meshes/fr_1.stl</uri>
            </mesh>
          </geometry>
          <surface>
            <contact>
              <ode />
            </contact>
            <friction>
              <ode>
                <mu>1.7</mu>
                <mu2>1.7</mu2>
              </ode>
            </friction>
          </surface>
        </collision>
        <visual name='fr_1_visual'>
          <pose>-0.875 -1.5174 0.1444 0 -0 0</pose>
          <geometry>
            <mesh>
              <scale>0.001 0.001 0.001</scale>
              <uri>model://autocar/meshes/fr_1.stl</uri>
            </mesh>
          </geometry>
          <material>
            <ambient>0.02 0.02 0.02 1</ambient>
            <diffuse>0.1 0.1 0.1 1</diffuse>
            <specular>0.4 0.4 0.4 1</specular>
          </material>
        </visual>
        <!--  <gravity>1</gravity> -->
        <!-- <velocity_decay/> -->
        <self_collide>1</self_collide>
      </link>

      <link name="steering_wheel" />

      <joint name="steering_joint" type="revolute">
        <pose>-0.002 0 0 0 0 0</pose>
        <parent>chassis_link</parent>
        <child>steering_wheel</child>
        <axis>
          <xyz>-0.964118 0.000768 0.265556</xyz>
          <limit>
            <lower>-100</lower>
            <upper>100</upper>
          </limit>
          <dynamics>
            <damping>1.0</damping>
          </dynamics>
          <use_parent_model_frame>true</use_parent_model_frame>
        </axis>
        <physics>
          <ode>
            <cfm_damping>1</cfm_damping>
          </ode>
        </physics>
      </joint>

      <plugin name='ackermann_drive' filename='libgazebo_ros_ackermann_drive.so'>

        <ros>
          <namespace>autocar</namespace>
          <remapping>cmd_vel:=cmd_vel</remapping>
          <remapping>odom:=odom</remapping>
          <remapping>distance:=distance</remapping>
        </ros>

        <update_rate>100.0</update_rate>

        <!-- wheels -->
        <front_left_joint>fl_axle</front_left_joint>
        <front_right_joint>fr_axle</front_right_joint>
        <rear_left_joint>bl_axle</rear_left_joint>
        <rear_right_joint>br_axle</rear_right_joint>
        <left_steering_joint>l_steer</left_steering_joint>
        <right_steering_joint>r_steer</right_steering_joint>
        <steering_wheel_joint>steering_joint</steering_wheel_joint>


        <!-- Max absolute steer angle for tyre in radians-->
        <!-- Any cmd_vel angular z greater than this would be capped -->
        <max_steer>0.85</max_steer>

        <!-- Max absolute steering angle of steering wheel -->
        <!-- Max absolute steering angle of steering wheel -->
        <max_steering_angle>7.85</max_steering_angle>

        <!-- Max absolute linear speed in m/s -->
        <max_speed>20</max_speed>

        <!-- PID tuning -->
        <left_steering_pid_gain>4000 0 1</left_steering_pid_gain>
        <left_steering_i_range>0 0</left_steering_i_range>
        <right_steering_pid_gain>4000 0 1</right_steering_pid_gain>
        <right_steering_i_range>0 0</right_steering_i_range>
        <linear_velocity_pid_gain>4000 0 1</linear_velocity_pid_gain>
        <linear_velocity_i_range>0 0</linear_velocity_i_range>

        <!-- output -->
        <publish_odom>true</publish_odom>
        <publish_odom_tf>true</publish_odom_tf>
        <publish_wheel_tf>true</publish_wheel_tf>
        <publish_distance>true</publish_distance>

        <odometry_frame>odom</odometry_frame>
        <robot_base_frame>base_link</robot_base_frame>

      </plugin>

    </model>

    <!-- ===== Race-track (visual road following the waypoint loop) ===== -->
    <road name="track">
      <width>16.0</width>
      <point>103.670 0.000 0</point>
      <point>102.661 14.428 0</point>
      <point>99.654 28.575 0</point>
      <point>94.707 42.166 0</point>
      <point>87.917 54.937 0</point>
      <point>79.416 66.638 0</point>
      <point>69.369 77.042 0</point>
      <point>57.972 85.946 0</point>
      <point>45.446 93.178 0</point>
      <point>32.036 98.596 0</point>
      <point>18.002 102.095 0</point>
      <point>3.618 103.607 0</point>
      <point>-10.836 103.102 0</point>
      <point>-25.080 100.591 0</point>
      <point>-38.835 96.121 0</point>
      <point>-51.835 89.781 0</point>
      <point>-63.826 81.693 0</point>
      <point>-74.574 72.015 0</point>
      <point>-83.871 60.936 0</point>
      <point>-91.535 48.670 0</point>
      <point>-97.418 35.457 0</point>
      <point>-101.405 21.554 0</point>
      <point>-103.417 7.232 0</point>
      <point>-103.417 -7.232 0</point>
      <point>-101.405 -21.554 0</point>
      <point>-97.418 -35.457 0</point>
      <point>-91.535 -48.670 0</point>
      <point>-83.871 -60.936 0</point>
      <point>-74.574 -72.015 0</point>
      <point>-63.826 -81.693 0</point>
      <point>-51.835 -89.781 0</point>
      <point>-38.835 -96.121 0</point>
      <point>-25.080 -100.591 0</point>
      <point>-10.836 -103.102 0</point>
      <point>3.618 -103.607 0</point>
      <point>18.002 -102.095 0</point>
      <point>32.036 -98.596 0</point>
      <point>45.446 -93.178 0</point>
      <point>57.972 -85.946 0</point>
      <point>69.369 -77.042 0</point>
      <point>79.416 -66.638 0</point>
      <point>87.917 -54.937 0</point>
      <point>94.707 -42.166 0</point>
      <point>99.654 -28.575 0</point>
      <point>102.661 -14.428 0</point>
      <point>103.670 0.000 0</point>
    </road>

    <!-- ===== Decorative hay bales bordering the track =====
         48 cylinders along the inside (r=92m) and outside (r=114m) of
         the 16m-wide race road. They are off-track so the planner does
         not need to avoid them; pure scenery for the wheat-field look. -->

    <model name="haybale_in_00">
      <static>true</static><pose>92.00 0.00 0.55 0 0 0</pose>
      <link name="link">
        <collision name="col"><geometry><cylinder><radius>0.55</radius><length>1.1</length></cylinder></geometry></collision>
        <visual name="vis"><geometry><cylinder><radius>0.55</radius><length>1.1</length></cylinder></geometry>
          <material><ambient>0.45 0.35 0.12 1</ambient><diffuse>0.78 0.62 0.25 1</diffuse><specular>0.1 0.1 0.05 1</specular></material></visual>
      </link>
    </model>
    <model name="haybale_out_00">
      <static>true</static><pose>114.00 0.00 0.55 0 0 0</pose>
      <link name="link">
        <collision name="col"><geometry><cylinder><radius>0.55</radius><length>1.1</length></cylinder></geometry></collision>
        <visual name="vis"><geometry><cylinder><radius>0.55</radius><length>1.1</length></cylinder></geometry>
          <material><ambient>0.45 0.35 0.12 1</ambient><diffuse>0.78 0.62 0.25 1</diffuse><specular>0.1 0.1 0.05 1</specular></material></visual>
      </link>
    </model>
    <model name="haybale_in_01">
      <static>true</static><pose>88.87 23.81 0.55 0 0 0</pose>
      <link name="link">
        <collision name="col"><geometry><cylinder><radius>0.55</radius><length>1.1</length></cylinder></geometry></collision>
        <visual name="vis"><geometry><cylinder><radius>0.55</radius><length>1.1</length></cylinder></geometry>
          <material><ambient>0.45 0.35 0.12 1</ambient><diffuse>0.78 0.62 0.25 1</diffuse><specular>0.1 0.1 0.05 1</specular></material></visual>
      </link>
    </model>
    <model name="haybale_out_01">
      <static>true</static><pose>110.12 29.51 0.55 0 0 0</pose>
      <link name="link">
        <collision name="col"><geometry><cylinder><radius>0.55</radius><length>1.1</length></cylinder></geometry></collision>
        <visual name="vis"><geometry><cylinder><radius>0.55</radius><length>1.1</length></cylinder></geometry>
          <material><ambient>0.45 0.35 0.12 1</ambient><diffuse>0.78 0.62 0.25 1</diffuse><specular>0.1 0.1 0.05 1</specular></material></visual>
      </link>
    </model>
    <model name="haybale_in_02">
      <static>true</static><pose>79.67 46.00 0.55 0 0 0</pose>
      <link name="link">
        <collision name="col"><geometry><cylinder><radius>0.55</radius><length>1.1</length></cylinder></geometry></collision>
        <visual name="vis"><geometry><cylinder><radius>0.55</radius><length>1.1</length></cylinder></geometry>
          <material><ambient>0.45 0.35 0.12 1</ambient><diffuse>0.78 0.62 0.25 1</diffuse><specular>0.1 0.1 0.05 1</specular></material></visual>
      </link>
    </model>
    <model name="haybale_out_02">
      <static>true</static><pose>98.73 57.00 0.55 0 0 0</pose>
      <link name="link">
        <collision name="col"><geometry><cylinder><radius>0.55</radius><length>1.1</length></cylinder></geometry></collision>
        <visual name="vis"><geometry><cylinder><radius>0.55</radius><length>1.1</length></cylinder></geometry>
          <material><ambient>0.45 0.35 0.12 1</ambient><diffuse>0.78 0.62 0.25 1</diffuse><specular>0.1 0.1 0.05 1</specular></material></visual>
      </link>
    </model>
    <model name="haybale_in_03">
      <static>true</static><pose>65.05 65.05 0.55 0 0 0</pose>
      <link name="link">
        <collision name="col"><geometry><cylinder><radius>0.55</radius><length>1.1</length></cylinder></geometry></collision>
        <visual name="vis"><geometry><cylinder><radius>0.55</radius><length>1.1</length></cylinder></geometry>
          <material><ambient>0.45 0.35 0.12 1</ambient><diffuse>0.78 0.62 0.25 1</diffuse><specular>0.1 0.1 0.05 1</specular></material></visual>
      </link>
    </model>
    <model name="haybale_out_03">
      <static>true</static><pose>80.61 80.61 0.55 0 0 0</pose>
      <link name="link">
        <collision name="col"><geometry><cylinder><radius>0.55</radius><length>1.1</length></cylinder></geometry></collision>
        <visual name="vis"><geometry><cylinder><radius>0.55</radius><length>1.1</length></cylinder></geometry>
          <material><ambient>0.45 0.35 0.12 1</ambient><diffuse>0.78 0.62 0.25 1</diffuse><specular>0.1 0.1 0.05 1</specular></material></visual>
      </link>
    </model>
    <model name="haybale_in_04">
      <static>true</static><pose>46.00 79.67 0.55 0 0 0</pose>
      <link name="link">
        <collision name="col"><geometry><cylinder><radius>0.55</radius><length>1.1</length></cylinder></geometry></collision>
        <visual name="vis"><geometry><cylinder><radius>0.55</radius><length>1.1</length></cylinder></geometry>
          <material><ambient>0.45 0.35 0.12 1</ambient><diffuse>0.78 0.62 0.25 1</diffuse><specular>0.1 0.1 0.05 1</specular></material></visual>
      </link>
    </model>
    <model name="haybale_out_04">
      <static>true</static><pose>57.00 98.73 0.55 0 0 0</pose>
      <link name="link">
        <collision name="col"><geometry><cylinder><radius>0.55</radius><length>1.1</length></cylinder></geometry></collision>
        <visual name="vis"><geometry><cylinder><radius>0.55</radius><length>1.1</length></cylinder></geometry>
          <material><ambient>0.45 0.35 0.12 1</ambient><diffuse>0.78 0.62 0.25 1</diffuse><specular>0.1 0.1 0.05 1</specular></material></visual>
      </link>
    </model>
    <model name="haybale_in_05">
      <static>true</static><pose>23.81 88.87 0.55 0 0 0</pose>
      <link name="link">
        <collision name="col"><geometry><cylinder><radius>0.55</radius><length>1.1</length></cylinder></geometry></collision>
        <visual name="vis"><geometry><cylinder><radius>0.55</radius><length>1.1</length></cylinder></geometry>
          <material><ambient>0.45 0.35 0.12 1</ambient><diffuse>0.78 0.62 0.25 1</diffuse><specular>0.1 0.1 0.05 1</specular></material></visual>
      </link>
    </model>
    <model name="haybale_out_05">
      <static>true</static><pose>29.51 110.12 0.55 0 0 0</pose>
      <link name="link">
        <collision name="col"><geometry><cylinder><radius>0.55</radius><length>1.1</length></cylinder></geometry></collision>
        <visual name="vis"><geometry><cylinder><radius>0.55</radius><length>1.1</length></cylinder></geometry>
          <material><ambient>0.45 0.35 0.12 1</ambient><diffuse>0.78 0.62 0.25 1</diffuse><specular>0.1 0.1 0.05 1</specular></material></visual>
      </link>
    </model>
    <model name="haybale_in_06">
      <static>true</static><pose>0.00 92.00 0.55 0 0 0</pose>
      <link name="link">
        <collision name="col"><geometry><cylinder><radius>0.55</radius><length>1.1</length></cylinder></geometry></collision>
        <visual name="vis"><geometry><cylinder><radius>0.55</radius><length>1.1</length></cylinder></geometry>
          <material><ambient>0.45 0.35 0.12 1</ambient><diffuse>0.78 0.62 0.25 1</diffuse><specular>0.1 0.1 0.05 1</specular></material></visual>
      </link>
    </model>
    <model name="haybale_out_06">
      <static>true</static><pose>0.00 114.00 0.55 0 0 0</pose>
      <link name="link">
        <collision name="col"><geometry><cylinder><radius>0.55</radius><length>1.1</length></cylinder></geometry></collision>
        <visual name="vis"><geometry><cylinder><radius>0.55</radius><length>1.1</length></cylinder></geometry>
          <material><ambient>0.45 0.35 0.12 1</ambient><diffuse>0.78 0.62 0.25 1</diffuse><specular>0.1 0.1 0.05 1</specular></material></visual>
      </link>
    </model>
    <model name="haybale_in_07">
      <static>true</static><pose>-23.81 88.87 0.55 0 0 0</pose>
      <link name="link">
        <collision name="col"><geometry><cylinder><radius>0.55</radius><length>1.1</length></cylinder></geometry></collision>
        <visual name="vis"><geometry><cylinder><radius>0.55</radius><length>1.1</length></cylinder></geometry>
          <material><ambient>0.45 0.35 0.12 1</ambient><diffuse>0.78 0.62 0.25 1</diffuse><specular>0.1 0.1 0.05 1</specular></material></visual>
      </link>
    </model>
    <model name="haybale_out_07">
      <static>true</static><pose>-29.51 110.12 0.55 0 0 0</pose>
      <link name="link">
        <collision name="col"><geometry><cylinder><radius>0.55</radius><length>1.1</length></cylinder></geometry></collision>
        <visual name="vis"><geometry><cylinder><radius>0.55</radius><length>1.1</length></cylinder></geometry>
          <material><ambient>0.45 0.35 0.12 1</ambient><diffuse>0.78 0.62 0.25 1</diffuse><specular>0.1 0.1 0.05 1</specular></material></visual>
      </link>
    </model>
    <model name="haybale_in_08">
      <static>true</static><pose>-46.00 79.67 0.55 0 0 0</pose>
      <link name="link">
        <collision name="col"><geometry><cylinder><radius>0.55</radius><length>1.1</length></cylinder></geometry></collision>
        <visual name="vis"><geometry><cylinder><radius>0.55</radius><length>1.1</length></cylinder></geometry>
          <material><ambient>0.45 0.35 0.12 1</ambient><diffuse>0.78 0.62 0.25 1</diffuse><specular>0.1 0.1 0.05 1</specular></material></visual>
      </link>
    </model>
    <model name="haybale_out_08">
      <static>true</static><pose>-57.00 98.73 0.55 0 0 0</pose>
      <link name="link">
        <collision name="col"><geometry><cylinder><radius>0.55</radius><length>1.1</length></cylinder></geometry></collision>
        <visual name="vis"><geometry><cylinder><radius>0.55</radius><length>1.1</length></cylinder></geometry>
          <material><ambient>0.45 0.35 0.12 1</ambient><diffuse>0.78 0.62 0.25 1</diffuse><specular>0.1 0.1 0.05 1</specular></material></visual>
      </link>
    </model>
    <model name="haybale_in_09">
      <static>true</static><pose>-65.05 65.05 0.55 0 0 0</pose>
      <link name="link">
        <collision name="col"><geometry><cylinder><radius>0.55</radius><length>1.1</length></cylinder></geometry></collision>
        <visual name="vis"><geometry><cylinder><radius>0.55</radius><length>1.1</length></cylinder></geometry>
          <material><ambient>0.45 0.35 0.12 1</ambient><diffuse>0.78 0.62 0.25 1</diffuse><specular>0.1 0.1 0.05 1</specular></material></visual>
      </link>
    </model>
    <model name="haybale_out_09">
      <static>true</static><pose>-80.61 80.61 0.55 0 0 0</pose>
      <link name="link">
        <collision name="col"><geometry><cylinder><radius>0.55</radius><length>1.1</length></cylinder></geometry></collision>
        <visual name="vis"><geometry><cylinder><radius>0.55</radius><length>1.1</length></cylinder></geometry>
          <material><ambient>0.45 0.35 0.12 1</ambient><diffuse>0.78 0.62 0.25 1</diffuse><specular>0.1 0.1 0.05 1</specular></material></visual>
      </link>
    </model>
    <model name="haybale_in_10">
      <static>true</static><pose>-79.67 46.00 0.55 0 0 0</pose>
      <link name="link">
        <collision name="col"><geometry><cylinder><radius>0.55</radius><length>1.1</length></cylinder></geometry></collision>
        <visual name="vis"><geometry><cylinder><radius>0.55</radius><length>1.1</length></cylinder></geometry>
          <material><ambient>0.45 0.35 0.12 1</ambient><diffuse>0.78 0.62 0.25 1</diffuse><specular>0.1 0.1 0.05 1</specular></material></visual>
      </link>
    </model>
    <model name="haybale_out_10">
      <static>true</static><pose>-98.73 57.00 0.55 0 0 0</pose>
      <link name="link">
        <collision name="col"><geometry><cylinder><radius>0.55</radius><length>1.1</length></cylinder></geometry></collision>
        <visual name="vis"><geometry><cylinder><radius>0.55</radius><length>1.1</length></cylinder></geometry>
          <material><ambient>0.45 0.35 0.12 1</ambient><diffuse>0.78 0.62 0.25 1</diffuse><specular>0.1 0.1 0.05 1</specular></material></visual>
      </link>
    </model>
    <model name="haybale_in_11">
      <static>true</static><pose>-88.87 23.81 0.55 0 0 0</pose>
      <link name="link">
        <collision name="col"><geometry><cylinder><radius>0.55</radius><length>1.1</length></cylinder></geometry></collision>
        <visual name="vis"><geometry><cylinder><radius>0.55</radius><length>1.1</length></cylinder></geometry>
          <material><ambient>0.45 0.35 0.12 1</ambient><diffuse>0.78 0.62 0.25 1</diffuse><specular>0.1 0.1 0.05 1</specular></material></visual>
      </link>
    </model>
    <model name="haybale_out_11">
      <static>true</static><pose>-110.12 29.51 0.55 0 0 0</pose>
      <link name="link">
        <collision name="col"><geometry><cylinder><radius>0.55</radius><length>1.1</length></cylinder></geometry></collision>
        <visual name="vis"><geometry><cylinder><radius>0.55</radius><length>1.1</length></cylinder></geometry>
          <material><ambient>0.45 0.35 0.12 1</ambient><diffuse>0.78 0.62 0.25 1</diffuse><specular>0.1 0.1 0.05 1</specular></material></visual>
      </link>
    </model>
    <model name="haybale_in_12">
      <static>true</static><pose>-92.00 0.00 0.55 0 0 0</pose>
      <link name="link">
        <collision name="col"><geometry><cylinder><radius>0.55</radius><length>1.1</length></cylinder></geometry></collision>
        <visual name="vis"><geometry><cylinder><radius>0.55</radius><length>1.1</length></cylinder></geometry>
          <material><ambient>0.45 0.35 0.12 1</ambient><diffuse>0.78 0.62 0.25 1</diffuse><specular>0.1 0.1 0.05 1</specular></material></visual>
      </link>
    </model>
    <model name="haybale_out_12">
      <static>true</static><pose>-114.00 0.00 0.55 0 0 0</pose>
      <link name="link">
        <collision name="col"><geometry><cylinder><radius>0.55</radius><length>1.1</length></cylinder></geometry></collision>
        <visual name="vis"><geometry><cylinder><radius>0.55</radius><length>1.1</length></cylinder></geometry>
          <material><ambient>0.45 0.35 0.12 1</ambient><diffuse>0.78 0.62 0.25 1</diffuse><specular>0.1 0.1 0.05 1</specular></material></visual>
      </link>
    </model>
    <model name="haybale_in_13">
      <static>true</static><pose>-88.87 -23.81 0.55 0 0 0</pose>
      <link name="link">
        <collision name="col"><geometry><cylinder><radius>0.55</radius><length>1.1</length></cylinder></geometry></collision>
        <visual name="vis"><geometry><cylinder><radius>0.55</radius><length>1.1</length></cylinder></geometry>
          <material><ambient>0.45 0.35 0.12 1</ambient><diffuse>0.78 0.62 0.25 1</diffuse><specular>0.1 0.1 0.05 1</specular></material></visual>
      </link>
    </model>
    <model name="haybale_out_13">
      <static>true</static><pose>-110.12 -29.51 0.55 0 0 0</pose>
      <link name="link">
        <collision name="col"><geometry><cylinder><radius>0.55</radius><length>1.1</length></cylinder></geometry></collision>
        <visual name="vis"><geometry><cylinder><radius>0.55</radius><length>1.1</length></cylinder></geometry>
          <material><ambient>0.45 0.35 0.12 1</ambient><diffuse>0.78 0.62 0.25 1</diffuse><specular>0.1 0.1 0.05 1</specular></material></visual>
      </link>
    </model>
    <model name="haybale_in_14">
      <static>true</static><pose>-79.67 -46.00 0.55 0 0 0</pose>
      <link name="link">
        <collision name="col"><geometry><cylinder><radius>0.55</radius><length>1.1</length></cylinder></geometry></collision>
        <visual name="vis"><geometry><cylinder><radius>0.55</radius><length>1.1</length></cylinder></geometry>
          <material><ambient>0.45 0.35 0.12 1</ambient><diffuse>0.78 0.62 0.25 1</diffuse><specular>0.1 0.1 0.05 1</specular></material></visual>
      </link>
    </model>
    <model name="haybale_out_14">
      <static>true</static><pose>-98.73 -57.00 0.55 0 0 0</pose>
      <link name="link">
        <collision name="col"><geometry><cylinder><radius>0.55</radius><length>1.1</length></cylinder></geometry></collision>
        <visual name="vis"><geometry><cylinder><radius>0.55</radius><length>1.1</length></cylinder></geometry>
          <material><ambient>0.45 0.35 0.12 1</ambient><diffuse>0.78 0.62 0.25 1</diffuse><specular>0.1 0.1 0.05 1</specular></material></visual>
      </link>
    </model>
    <model name="haybale_in_15">
      <static>true</static><pose>-65.05 -65.05 0.55 0 0 0</pose>
      <link name="link">
        <collision name="col"><geometry><cylinder><radius>0.55</radius><length>1.1</length></cylinder></geometry></collision>
        <visual name="vis"><geometry><cylinder><radius>0.55</radius><length>1.1</length></cylinder></geometry>
          <material><ambient>0.45 0.35 0.12 1</ambient><diffuse>0.78 0.62 0.25 1</diffuse><specular>0.1 0.1 0.05 1</specular></material></visual>
      </link>
    </model>
    <model name="haybale_out_15">
      <static>true</static><pose>-80.61 -80.61 0.55 0 0 0</pose>
      <link name="link">
        <collision name="col"><geometry><cylinder><radius>0.55</radius><length>1.1</length></cylinder></geometry></collision>
        <visual name="vis"><geometry><cylinder><radius>0.55</radius><length>1.1</length></cylinder></geometry>
          <material><ambient>0.45 0.35 0.12 1</ambient><diffuse>0.78 0.62 0.25 1</diffuse><specular>0.1 0.1 0.05 1</specular></material></visual>
      </link>
    </model>
    <model name="haybale_in_16">
      <static>true</static><pose>-46.00 -79.67 0.55 0 0 0</pose>
      <link name="link">
        <collision name="col"><geometry><cylinder><radius>0.55</radius><length>1.1</length></cylinder></geometry></collision>
        <visual name="vis"><geometry><cylinder><radius>0.55</radius><length>1.1</length></cylinder></geometry>
          <material><ambient>0.45 0.35 0.12 1</ambient><diffuse>0.78 0.62 0.25 1</diffuse><specular>0.1 0.1 0.05 1</specular></material></visual>
      </link>
    </model>
    <model name="haybale_out_16">
      <static>true</static><pose>-57.00 -98.73 0.55 0 0 0</pose>
      <link name="link">
        <collision name="col"><geometry><cylinder><radius>0.55</radius><length>1.1</length></cylinder></geometry></collision>
        <visual name="vis"><geometry><cylinder><radius>0.55</radius><length>1.1</length></cylinder></geometry>
          <material><ambient>0.45 0.35 0.12 1</ambient><diffuse>0.78 0.62 0.25 1</diffuse><specular>0.1 0.1 0.05 1</specular></material></visual>
      </link>
    </model>
    <model name="haybale_in_17">
      <static>true</static><pose>-23.81 -88.87 0.55 0 0 0</pose>
      <link name="link">
        <collision name="col"><geometry><cylinder><radius>0.55</radius><length>1.1</length></cylinder></geometry></collision>
        <visual name="vis"><geometry><cylinder><radius>0.55</radius><length>1.1</length></cylinder></geometry>
          <material><ambient>0.45 0.35 0.12 1</ambient><diffuse>0.78 0.62 0.25 1</diffuse><specular>0.1 0.1 0.05 1</specular></material></visual>
      </link>
    </model>
    <model name="haybale_out_17">
      <static>true</static><pose>-29.51 -110.12 0.55 0 0 0</pose>
      <link name="link">
        <collision name="col"><geometry><cylinder><radius>0.55</radius><length>1.1</length></cylinder></geometry></collision>
        <visual name="vis"><geometry><cylinder><radius>0.55</radius><length>1.1</length></cylinder></geometry>
          <material><ambient>0.45 0.35 0.12 1</ambient><diffuse>0.78 0.62 0.25 1</diffuse><specular>0.1 0.1 0.05 1</specular></material></visual>
      </link>
    </model>
    <model name="haybale_in_18">
      <static>true</static><pose>-0.00 -92.00 0.55 0 0 0</pose>
      <link name="link">
        <collision name="col"><geometry><cylinder><radius>0.55</radius><length>1.1</length></cylinder></geometry></collision>
        <visual name="vis"><geometry><cylinder><radius>0.55</radius><length>1.1</length></cylinder></geometry>
          <material><ambient>0.45 0.35 0.12 1</ambient><diffuse>0.78 0.62 0.25 1</diffuse><specular>0.1 0.1 0.05 1</specular></material></visual>
      </link>
    </model>
    <model name="haybale_out_18">
      <static>true</static><pose>-0.00 -114.00 0.55 0 0 0</pose>
      <link name="link">
        <collision name="col"><geometry><cylinder><radius>0.55</radius><length>1.1</length></cylinder></geometry></collision>
        <visual name="vis"><geometry><cylinder><radius>0.55</radius><length>1.1</length></cylinder></geometry>
          <material><ambient>0.45 0.35 0.12 1</ambient><diffuse>0.78 0.62 0.25 1</diffuse><specular>0.1 0.1 0.05 1</specular></material></visual>
      </link>
    </model>
    <model name="haybale_in_19">
      <static>true</static><pose>23.81 -88.87 0.55 0 0 0</pose>
      <link name="link">
        <collision name="col"><geometry><cylinder><radius>0.55</radius><length>1.1</length></cylinder></geometry></collision>
        <visual name="vis"><geometry><cylinder><radius>0.55</radius><length>1.1</length></cylinder></geometry>
          <material><ambient>0.45 0.35 0.12 1</ambient><diffuse>0.78 0.62 0.25 1</diffuse><specular>0.1 0.1 0.05 1</specular></material></visual>
      </link>
    </model>
    <model name="haybale_out_19">
      <static>true</static><pose>29.51 -110.12 0.55 0 0 0</pose>
      <link name="link">
        <collision name="col"><geometry><cylinder><radius>0.55</radius><length>1.1</length></cylinder></geometry></collision>
        <visual name="vis"><geometry><cylinder><radius>0.55</radius><length>1.1</length></cylinder></geometry>
          <material><ambient>0.45 0.35 0.12 1</ambient><diffuse>0.78 0.62 0.25 1</diffuse><specular>0.1 0.1 0.05 1</specular></material></visual>
      </link>
    </model>
    <model name="haybale_in_20">
      <static>true</static><pose>46.00 -79.67 0.55 0 0 0</pose>
      <link name="link">
        <collision name="col"><geometry><cylinder><radius>0.55</radius><length>1.1</length></cylinder></geometry></collision>
        <visual name="vis"><geometry><cylinder><radius>0.55</radius><length>1.1</length></cylinder></geometry>
          <material><ambient>0.45 0.35 0.12 1</ambient><diffuse>0.78 0.62 0.25 1</diffuse><specular>0.1 0.1 0.05 1</specular></material></visual>
      </link>
    </model>
    <model name="haybale_out_20">
      <static>true</static><pose>57.00 -98.73 0.55 0 0 0</pose>
      <link name="link">
        <collision name="col"><geometry><cylinder><radius>0.55</radius><length>1.1</length></cylinder></geometry></collision>
        <visual name="vis"><geometry><cylinder><radius>0.55</radius><length>1.1</length></cylinder></geometry>
          <material><ambient>0.45 0.35 0.12 1</ambient><diffuse>0.78 0.62 0.25 1</diffuse><specular>0.1 0.1 0.05 1</specular></material></visual>
      </link>
    </model>
    <model name="haybale_in_21">
      <static>true</static><pose>65.05 -65.05 0.55 0 0 0</pose>
      <link name="link">
        <collision name="col"><geometry><cylinder><radius>0.55</radius><length>1.1</length></cylinder></geometry></collision>
        <visual name="vis"><geometry><cylinder><radius>0.55</radius><length>1.1</length></cylinder></geometry>
          <material><ambient>0.45 0.35 0.12 1</ambient><diffuse>0.78 0.62 0.25 1</diffuse><specular>0.1 0.1 0.05 1</specular></material></visual>
      </link>
    </model>
    <model name="haybale_out_21">
      <static>true</static><pose>80.61 -80.61 0.55 0 0 0</pose>
      <link name="link">
        <collision name="col"><geometry><cylinder><radius>0.55</radius><length>1.1</length></cylinder></geometry></collision>
        <visual name="vis"><geometry><cylinder><radius>0.55</radius><length>1.1</length></cylinder></geometry>
          <material><ambient>0.45 0.35 0.12 1</ambient><diffuse>0.78 0.62 0.25 1</diffuse><specular>0.1 0.1 0.05 1</specular></material></visual>
      </link>
    </model>
    <model name="haybale_in_22">
      <static>true</static><pose>79.67 -46.00 0.55 0 0 0</pose>
      <link name="link">
        <collision name="col"><geometry><cylinder><radius>0.55</radius><length>1.1</length></cylinder></geometry></collision>
        <visual name="vis"><geometry><cylinder><radius>0.55</radius><length>1.1</length></cylinder></geometry>
          <material><ambient>0.45 0.35 0.12 1</ambient><diffuse>0.78 0.62 0.25 1</diffuse><specular>0.1 0.1 0.05 1</specular></material></visual>
      </link>
    </model>
    <model name="haybale_out_22">
      <static>true</static><pose>98.73 -57.00 0.55 0 0 0</pose>
      <link name="link">
        <collision name="col"><geometry><cylinder><radius>0.55</radius><length>1.1</length></cylinder></geometry></collision>
        <visual name="vis"><geometry><cylinder><radius>0.55</radius><length>1.1</length></cylinder></geometry>
          <material><ambient>0.45 0.35 0.12 1</ambient><diffuse>0.78 0.62 0.25 1</diffuse><specular>0.1 0.1 0.05 1</specular></material></visual>
      </link>
    </model>
    <model name="haybale_in_23">
      <static>true</static><pose>88.87 -23.81 0.55 0 0 0</pose>
      <link name="link">
        <collision name="col"><geometry><cylinder><radius>0.55</radius><length>1.1</length></cylinder></geometry></collision>
        <visual name="vis"><geometry><cylinder><radius>0.55</radius><length>1.1</length></cylinder></geometry>
          <material><ambient>0.45 0.35 0.12 1</ambient><diffuse>0.78 0.62 0.25 1</diffuse><specular>0.1 0.1 0.05 1</specular></material></visual>
      </link>
    </model>
    <model name="haybale_out_23">
      <static>true</static><pose>110.12 -29.51 0.55 0 0 0</pose>
      <link name="link">
        <collision name="col"><geometry><cylinder><radius>0.55</radius><length>1.1</length></cylinder></geometry></collision>
        <visual name="vis"><geometry><cylinder><radius>0.55</radius><length>1.1</length></cylinder></geometry>
          <material><ambient>0.45 0.35 0.12 1</ambient><diffuse>0.78 0.62 0.25 1</diffuse><specular>0.1 0.1 0.05 1</specular></material></visual>
      </link>
    </model>

    <model name="track_inner_guardrail">
      <static>true</static>
      <link name="seg_00"><pose>96.00 0.00 0.55 0 0 1.5708</pose><collision name="col"><geometry><box><size>24.0 1.2 1.1</size></box></geometry></collision><visual name="vis"><geometry><box><size>24.0 1.2 1.1</size></box></geometry><material><ambient>0.12 0.12 0.12 1</ambient><diffuse>0.45 0.45 0.42 1</diffuse><specular>0.1 0.1 0.1 1</specular></material></visual></link>
      <link name="seg_01"><pose>92.73 24.85 0.55 0 0 1.8326</pose><collision name="col"><geometry><box><size>24.0 1.2 1.1</size></box></geometry></collision><visual name="vis"><geometry><box><size>24.0 1.2 1.1</size></box></geometry><material><ambient>0.12 0.12 0.12 1</ambient><diffuse>0.45 0.45 0.42 1</diffuse><specular>0.1 0.1 0.1 1</specular></material></visual></link>
      <link name="seg_02"><pose>83.14 48.00 0.55 0 0 2.0944</pose><collision name="col"><geometry><box><size>24.0 1.2 1.1</size></box></geometry></collision><visual name="vis"><geometry><box><size>24.0 1.2 1.1</size></box></geometry><material><ambient>0.12 0.12 0.12 1</ambient><diffuse>0.45 0.45 0.42 1</diffuse><specular>0.1 0.1 0.1 1</specular></material></visual></link>
      <link name="seg_03"><pose>67.88 67.88 0.55 0 0 2.3562</pose><collision name="col"><geometry><box><size>24.0 1.2 1.1</size></box></geometry></collision><visual name="vis"><geometry><box><size>24.0 1.2 1.1</size></box></geometry><material><ambient>0.12 0.12 0.12 1</ambient><diffuse>0.45 0.45 0.42 1</diffuse><specular>0.1 0.1 0.1 1</specular></material></visual></link>
      <link name="seg_04"><pose>48.00 83.14 0.55 0 0 2.6180</pose><collision name="col"><geometry><box><size>24.0 1.2 1.1</size></box></geometry></collision><visual name="vis"><geometry><box><size>24.0 1.2 1.1</size></box></geometry><material><ambient>0.12 0.12 0.12 1</ambient><diffuse>0.45 0.45 0.42 1</diffuse><specular>0.1 0.1 0.1 1</specular></material></visual></link>
      <link name="seg_05"><pose>24.85 92.73 0.55 0 0 2.8798</pose><collision name="col"><geometry><box><size>24.0 1.2 1.1</size></box></geometry></collision><visual name="vis"><geometry><box><size>24.0 1.2 1.1</size></box></geometry><material><ambient>0.12 0.12 0.12 1</ambient><diffuse>0.45 0.45 0.42 1</diffuse><specular>0.1 0.1 0.1 1</specular></material></visual></link>
      <link name="seg_06"><pose>0.00 96.00 0.55 0 0 3.1416</pose><collision name="col"><geometry><box><size>24.0 1.2 1.1</size></box></geometry></collision><visual name="vis"><geometry><box><size>24.0 1.2 1.1</size></box></geometry><material><ambient>0.12 0.12 0.12 1</ambient><diffuse>0.45 0.45 0.42 1</diffuse><specular>0.1 0.1 0.1 1</specular></material></visual></link>
      <link name="seg_07"><pose>-24.85 92.73 0.55 0 0 3.4034</pose><collision name="col"><geometry><box><size>24.0 1.2 1.1</size></box></geometry></collision><visual name="vis"><geometry><box><size>24.0 1.2 1.1</size></box></geometry><material><ambient>0.12 0.12 0.12 1</ambient><diffuse>0.45 0.45 0.42 1</diffuse><specular>0.1 0.1 0.1 1</specular></material></visual></link>
      <link name="seg_08"><pose>-48.00 83.14 0.55 0 0 3.6652</pose><collision name="col"><geometry><box><size>24.0 1.2 1.1</size></box></geometry></collision><visual name="vis"><geometry><box><size>24.0 1.2 1.1</size></box></geometry><material><ambient>0.12 0.12 0.12 1</ambient><diffuse>0.45 0.45 0.42 1</diffuse><specular>0.1 0.1 0.1 1</specular></material></visual></link>
      <link name="seg_09"><pose>-67.88 67.88 0.55 0 0 3.9270</pose><collision name="col"><geometry><box><size>24.0 1.2 1.1</size></box></geometry></collision><visual name="vis"><geometry><box><size>24.0 1.2 1.1</size></box></geometry><material><ambient>0.12 0.12 0.12 1</ambient><diffuse>0.45 0.45 0.42 1</diffuse><specular>0.1 0.1 0.1 1</specular></material></visual></link>
      <link name="seg_10"><pose>-83.14 48.00 0.55 0 0 4.1888</pose><collision name="col"><geometry><box><size>24.0 1.2 1.1</size></box></geometry></collision><visual name="vis"><geometry><box><size>24.0 1.2 1.1</size></box></geometry><material><ambient>0.12 0.12 0.12 1</ambient><diffuse>0.45 0.45 0.42 1</diffuse><specular>0.1 0.1 0.1 1</specular></material></visual></link>
      <link name="seg_11"><pose>-92.73 24.85 0.55 0 0 4.4506</pose><collision name="col"><geometry><box><size>24.0 1.2 1.1</size></box></geometry></collision><visual name="vis"><geometry><box><size>24.0 1.2 1.1</size></box></geometry><material><ambient>0.12 0.12 0.12 1</ambient><diffuse>0.45 0.45 0.42 1</diffuse><specular>0.1 0.1 0.1 1</specular></material></visual></link>
      <link name="seg_12"><pose>-96.00 0.00 0.55 0 0 4.7124</pose><collision name="col"><geometry><box><size>24.0 1.2 1.1</size></box></geometry></collision><visual name="vis"><geometry><box><size>24.0 1.2 1.1</size></box></geometry><material><ambient>0.12 0.12 0.12 1</ambient><diffuse>0.45 0.45 0.42 1</diffuse><specular>0.1 0.1 0.1 1</specular></material></visual></link>
      <link name="seg_13"><pose>-92.73 -24.85 0.55 0 0 4.9742</pose><collision name="col"><geometry><box><size>24.0 1.2 1.1</size></box></geometry></collision><visual name="vis"><geometry><box><size>24.0 1.2 1.1</size></box></geometry><material><ambient>0.12 0.12 0.12 1</ambient><diffuse>0.45 0.45 0.42 1</diffuse><specular>0.1 0.1 0.1 1</specular></material></visual></link>
      <link name="seg_14"><pose>-83.14 -48.00 0.55 0 0 5.2360</pose><collision name="col"><geometry><box><size>24.0 1.2 1.1</size></box></geometry></collision><visual name="vis"><geometry><box><size>24.0 1.2 1.1</size></box></geometry><material><ambient>0.12 0.12 0.12 1</ambient><diffuse>0.45 0.45 0.42 1</diffuse><specular>0.1 0.1 0.1 1</specular></material></visual></link>
      <link name="seg_15"><pose>-67.88 -67.88 0.55 0 0 5.4978</pose><collision name="col"><geometry><box><size>24.0 1.2 1.1</size></box></geometry></collision><visual name="vis"><geometry><box><size>24.0 1.2 1.1</size></box></geometry><material><ambient>0.12 0.12 0.12 1</ambient><diffuse>0.45 0.45 0.42 1</diffuse><specular>0.1 0.1 0.1 1</specular></material></visual></link>
      <link name="seg_16"><pose>-48.00 -83.14 0.55 0 0 5.7596</pose><collision name="col"><geometry><box><size>24.0 1.2 1.1</size></box></geometry></collision><visual name="vis"><geometry><box><size>24.0 1.2 1.1</size></box></geometry><material><ambient>0.12 0.12 0.12 1</ambient><diffuse>0.45 0.45 0.42 1</diffuse><specular>0.1 0.1 0.1 1</specular></material></visual></link>
      <link name="seg_17"><pose>-24.85 -92.73 0.55 0 0 6.0214</pose><collision name="col"><geometry><box><size>24.0 1.2 1.1</size></box></geometry></collision><visual name="vis"><geometry><box><size>24.0 1.2 1.1</size></box></geometry><material><ambient>0.12 0.12 0.12 1</ambient><diffuse>0.45 0.45 0.42 1</diffuse><specular>0.1 0.1 0.1 1</specular></material></visual></link>
      <link name="seg_18"><pose>0.00 -96.00 0.55 0 0 6.2832</pose><collision name="col"><geometry><box><size>24.0 1.2 1.1</size></box></geometry></collision><visual name="vis"><geometry><box><size>24.0 1.2 1.1</size></box></geometry><material><ambient>0.12 0.12 0.12 1</ambient><diffuse>0.45 0.45 0.42 1</diffuse><specular>0.1 0.1 0.1 1</specular></material></visual></link>
      <link name="seg_19"><pose>24.85 -92.73 0.55 0 0 6.5450</pose><collision name="col"><geometry><box><size>24.0 1.2 1.1</size></box></geometry></collision><visual name="vis"><geometry><box><size>24.0 1.2 1.1</size></box></geometry><material><ambient>0.12 0.12 0.12 1</ambient><diffuse>0.45 0.45 0.42 1</diffuse><specular>0.1 0.1 0.1 1</specular></material></visual></link>
      <link name="seg_20"><pose>48.00 -83.14 0.55 0 0 6.8068</pose><collision name="col"><geometry><box><size>24.0 1.2 1.1</size></box></geometry></collision><visual name="vis"><geometry><box><size>24.0 1.2 1.1</size></box></geometry><material><ambient>0.12 0.12 0.12 1</ambient><diffuse>0.45 0.45 0.42 1</diffuse><specular>0.1 0.1 0.1 1</specular></material></visual></link>
      <link name="seg_21"><pose>67.88 -67.88 0.55 0 0 7.0686</pose><collision name="col"><geometry><box><size>24.0 1.2 1.1</size></box></geometry></collision><visual name="vis"><geometry><box><size>24.0 1.2 1.1</size></box></geometry><material><ambient>0.12 0.12 0.12 1</ambient><diffuse>0.45 0.45 0.42 1</diffuse><specular>0.1 0.1 0.1 1</specular></material></visual></link>
      <link name="seg_22"><pose>83.14 -48.00 0.55 0 0 7.3304</pose><collision name="col"><geometry><box><size>24.0 1.2 1.1</size></box></geometry></collision><visual name="vis"><geometry><box><size>24.0 1.2 1.1</size></box></geometry><material><ambient>0.12 0.12 0.12 1</ambient><diffuse>0.45 0.45 0.42 1</diffuse><specular>0.1 0.1 0.1 1</specular></material></visual></link>
      <link name="seg_23"><pose>92.73 -24.85 0.55 0 0 7.5922</pose><collision name="col"><geometry><box><size>24.0 1.2 1.1</size></box></geometry></collision><visual name="vis"><geometry><box><size>24.0 1.2 1.1</size></box></geometry><material><ambient>0.12 0.12 0.12 1</ambient><diffuse>0.45 0.45 0.42 1</diffuse><specular>0.1 0.1 0.1 1</specular></material></visual></link>
    </model>

    <model name="track_outer_guardrail">
      <static>true</static>
      <link name="seg_00"><pose>112.00 0.00 0.55 0 0 1.5708</pose><collision name="col"><geometry><box><size>28.5 1.2 1.1</size></box></geometry></collision><visual name="vis"><geometry><box><size>28.5 1.2 1.1</size></box></geometry><material><ambient>0.12 0.12 0.12 1</ambient><diffuse>0.45 0.45 0.42 1</diffuse><specular>0.1 0.1 0.1 1</specular></material></visual></link>
      <link name="seg_01"><pose>108.18 28.99 0.55 0 0 1.8326</pose><collision name="col"><geometry><box><size>28.5 1.2 1.1</size></box></geometry></collision><visual name="vis"><geometry><box><size>28.5 1.2 1.1</size></box></geometry><material><ambient>0.12 0.12 0.12 1</ambient><diffuse>0.45 0.45 0.42 1</diffuse><specular>0.1 0.1 0.1 1</specular></material></visual></link>
      <link name="seg_02"><pose>96.99 56.00 0.55 0 0 2.0944</pose><collision name="col"><geometry><box><size>28.5 1.2 1.1</size></box></geometry></collision><visual name="vis"><geometry><box><size>28.5 1.2 1.1</size></box></geometry><material><ambient>0.12 0.12 0.12 1</ambient><diffuse>0.45 0.45 0.42 1</diffuse><specular>0.1 0.1 0.1 1</specular></material></visual></link>
      <link name="seg_03"><pose>79.20 79.20 0.55 0 0 2.3562</pose><collision name="col"><geometry><box><size>28.5 1.2 1.1</size></box></geometry></collision><visual name="vis"><geometry><box><size>28.5 1.2 1.1</size></box></geometry><material><ambient>0.12 0.12 0.12 1</ambient><diffuse>0.45 0.45 0.42 1</diffuse><specular>0.1 0.1 0.1 1</specular></material></visual></link>
      <link name="seg_04"><pose>56.00 96.99 0.55 0 0 2.6180</pose><collision name="col"><geometry><box><size>28.5 1.2 1.1</size></box></geometry></collision><visual name="vis"><geometry><box><size>28.5 1.2 1.1</size></box></geometry><material><ambient>0.12 0.12 0.12 1</ambient><diffuse>0.45 0.45 0.42 1</diffuse><specular>0.1 0.1 0.1 1</specular></material></visual></link>
      <link name="seg_05"><pose>28.99 108.18 0.55 0 0 2.8798</pose><collision name="col"><geometry><box><size>28.5 1.2 1.1</size></box></geometry></collision><visual name="vis"><geometry><box><size>28.5 1.2 1.1</size></box></geometry><material><ambient>0.12 0.12 0.12 1</ambient><diffuse>0.45 0.45 0.42 1</diffuse><specular>0.1 0.1 0.1 1</specular></material></visual></link>
      <link name="seg_06"><pose>0.00 112.00 0.55 0 0 3.1416</pose><collision name="col"><geometry><box><size>28.5 1.2 1.1</size></box></geometry></collision><visual name="vis"><geometry><box><size>28.5 1.2 1.1</size></box></geometry><material><ambient>0.12 0.12 0.12 1</ambient><diffuse>0.45 0.45 0.42 1</diffuse><specular>0.1 0.1 0.1 1</specular></material></visual></link>
      <link name="seg_07"><pose>-28.99 108.18 0.55 0 0 3.4034</pose><collision name="col"><geometry><box><size>28.5 1.2 1.1</size></box></geometry></collision><visual name="vis"><geometry><box><size>28.5 1.2 1.1</size></box></geometry><material><ambient>0.12 0.12 0.12 1</ambient><diffuse>0.45 0.45 0.42 1</diffuse><specular>0.1 0.1 0.1 1</specular></material></visual></link>
      <link name="seg_08"><pose>-56.00 96.99 0.55 0 0 3.6652</pose><collision name="col"><geometry><box><size>28.5 1.2 1.1</size></box></geometry></collision><visual name="vis"><geometry><box><size>28.5 1.2 1.1</size></box></geometry><material><ambient>0.12 0.12 0.12 1</ambient><diffuse>0.45 0.45 0.42 1</diffuse><specular>0.1 0.1 0.1 1</specular></material></visual></link>
      <link name="seg_09"><pose>-79.20 79.20 0.55 0 0 3.9270</pose><collision name="col"><geometry><box><size>28.5 1.2 1.1</size></box></geometry></collision><visual name="vis"><geometry><box><size>28.5 1.2 1.1</size></box></geometry><material><ambient>0.12 0.12 0.12 1</ambient><diffuse>0.45 0.45 0.42 1</diffuse><specular>0.1 0.1 0.1 1</specular></material></visual></link>
      <link name="seg_10"><pose>-96.99 56.00 0.55 0 0 4.1888</pose><collision name="col"><geometry><box><size>28.5 1.2 1.1</size></box></geometry></collision><visual name="vis"><geometry><box><size>28.5 1.2 1.1</size></box></geometry><material><ambient>0.12 0.12 0.12 1</ambient><diffuse>0.45 0.45 0.42 1</diffuse><specular>0.1 0.1 0.1 1</specular></material></visual></link>
      <link name="seg_11"><pose>-108.18 28.99 0.55 0 0 4.4506</pose><collision name="col"><geometry><box><size>28.5 1.2 1.1</size></box></geometry></collision><visual name="vis"><geometry><box><size>28.5 1.2 1.1</size></box></geometry><material><ambient>0.12 0.12 0.12 1</ambient><diffuse>0.45 0.45 0.42 1</diffuse><specular>0.1 0.1 0.1 1</specular></material></visual></link>
      <link name="seg_12"><pose>-112.00 0.00 0.55 0 0 4.7124</pose><collision name="col"><geometry><box><size>28.5 1.2 1.1</size></box></geometry></collision><visual name="vis"><geometry><box><size>28.5 1.2 1.1</size></box></geometry><material><ambient>0.12 0.12 0.12 1</ambient><diffuse>0.45 0.45 0.42 1</diffuse><specular>0.1 0.1 0.1 1</specular></material></visual></link>
      <link name="seg_13"><pose>-108.18 -28.99 0.55 0 0 4.9742</pose><collision name="col"><geometry><box><size>28.5 1.2 1.1</size></box></geometry></collision><visual name="vis"><geometry><box><size>28.5 1.2 1.1</size></box></geometry><material><ambient>0.12 0.12 0.12 1</ambient><diffuse>0.45 0.45 0.42 1</diffuse><specular>0.1 0.1 0.1 1</specular></material></visual></link>
      <link name="seg_14"><pose>-96.99 -56.00 0.55 0 0 5.2360</pose><collision name="col"><geometry><box><size>28.5 1.2 1.1</size></box></geometry></collision><visual name="vis"><geometry><box><size>28.5 1.2 1.1</size></box></geometry><material><ambient>0.12 0.12 0.12 1</ambient><diffuse>0.45 0.45 0.42 1</diffuse><specular>0.1 0.1 0.1 1</specular></material></visual></link>
      <link name="seg_15"><pose>-79.20 -79.20 0.55 0 0 5.4978</pose><collision name="col"><geometry><box><size>28.5 1.2 1.1</size></box></geometry></collision><visual name="vis"><geometry><box><size>28.5 1.2 1.1</size></box></geometry><material><ambient>0.12 0.12 0.12 1</ambient><diffuse>0.45 0.45 0.42 1</diffuse><specular>0.1 0.1 0.1 1</specular></material></visual></link>
      <link name="seg_16"><pose>-56.00 -96.99 0.55 0 0 5.7596</pose><collision name="col"><geometry><box><size>28.5 1.2 1.1</size></box></geometry></collision><visual name="vis"><geometry><box><size>28.5 1.2 1.1</size></box></geometry><material><ambient>0.12 0.12 0.12 1</ambient><diffuse>0.45 0.45 0.42 1</diffuse><specular>0.1 0.1 0.1 1</specular></material></visual></link>
      <link name="seg_17"><pose>-28.99 -108.18 0.55 0 0 6.0214</pose><collision name="col"><geometry><box><size>28.5 1.2 1.1</size></box></geometry></collision><visual name="vis"><geometry><box><size>28.5 1.2 1.1</size></box></geometry><material><ambient>0.12 0.12 0.12 1</ambient><diffuse>0.45 0.45 0.42 1</diffuse><specular>0.1 0.1 0.1 1</specular></material></visual></link>
      <link name="seg_18"><pose>0.00 -112.00 0.55 0 0 6.2832</pose><collision name="col"><geometry><box><size>28.5 1.2 1.1</size></box></geometry></collision><visual name="vis"><geometry><box><size>28.5 1.2 1.1</size></box></geometry><material><ambient>0.12 0.12 0.12 1</ambient><diffuse>0.45 0.45 0.42 1</diffuse><specular>0.1 0.1 0.1 1</specular></material></visual></link>
      <link name="seg_19"><pose>28.99 -108.18 0.55 0 0 6.5450</pose><collision name="col"><geometry><box><size>28.5 1.2 1.1</size></box></geometry></collision><visual name="vis"><geometry><box><size>28.5 1.2 1.1</size></box></geometry><material><ambient>0.12 0.12 0.12 1</ambient><diffuse>0.45 0.45 0.42 1</diffuse><specular>0.1 0.1 0.1 1</specular></material></visual></link>
      <link name="seg_20"><pose>56.00 -96.99 0.55 0 0 6.8068</pose><collision name="col"><geometry><box><size>28.5 1.2 1.1</size></box></geometry></collision><visual name="vis"><geometry><box><size>28.5 1.2 1.1</size></box></geometry><material><ambient>0.12 0.12 0.12 1</ambient><diffuse>0.45 0.45 0.42 1</diffuse><specular>0.1 0.1 0.1 1</specular></material></visual></link>
      <link name="seg_21"><pose>79.20 -79.20 0.55 0 0 7.0686</pose><collision name="col"><geometry><box><size>28.5 1.2 1.1</size></box></geometry></collision><visual name="vis"><geometry><box><size>28.5 1.2 1.1</size></box></geometry><material><ambient>0.12 0.12 0.12 1</ambient><diffuse>0.45 0.45 0.42 1</diffuse><specular>0.1 0.1 0.1 1</specular></material></visual></link>
      <link name="seg_22"><pose>96.99 -56.00 0.55 0 0 7.3304</pose><collision name="col"><geometry><box><size>28.5 1.2 1.1</size></box></geometry></collision><visual name="vis"><geometry><box><size>28.5 1.2 1.1</size></box></geometry><material><ambient>0.12 0.12 0.12 1</ambient><diffuse>0.45 0.45 0.42 1</diffuse><specular>0.1 0.1 0.1 1</specular></material></visual></link>
      <link name="seg_23"><pose>108.18 -28.99 0.55 0 0 7.5922</pose><collision name="col"><geometry><box><size>28.5 1.2 1.1</size></box></geometry></collision><visual name="vis"><geometry><box><size>28.5 1.2 1.1</size></box></geometry><material><ambient>0.12 0.12 0.12 1</ambient><diffuse>0.45 0.45 0.42 1</diffuse><specular>0.1 0.1 0.1 1</specular></material></visual></link>
    </model>

  </world>
</sdf>
